<?xml version="1.0" ?>
<!-- =================================================================================== -->
<!-- |    This document was autogenerated by xacro from src/mico_description/robots/standalone_arm_CB.urdf.xacro | -->
<!-- |    EDITING THIS FILE BY HAND IS NOT RECOMMENDED                                 | -->
<!-- =================================================================================== -->
<robot name="mico" xmlns:body="http://playerstage.sourceforge.net/gazebo/xmlschema/#body" xmlns:controller="http://playerstage.sourceforge.net/gazebo/xmlschema/#controller" xmlns:gazebo="http://playerstage.sourceforge.net/gazebo/xmlschema/#gz" xmlns:geom="http://playerstage.sourceforge.net/gazebo/xmlschema/#geom" xmlns:interface="http://playerstage.sourceforge.net/gazebo/xmlschema/#interface" xmlns:joint="http://playerstage.sourceforge.net/gazebo/xmlschema/#joint" xmlns:model="http://playerstage.sourceforge.net/gazebo/xmlschema/#model" xmlns:physics="http://playerstage.sourceforge.net/gazebo/xmlschema/#physics" xmlns:renderable="http://playerstage.sourceforge.net/gazebo/xmlschema/#renderable" xmlns:rendering="http://playerstage.sourceforge.net/gazebo/xmlschema/#rendering" xmlns:sensor="http://playerstage.sourceforge.net/gazebo/xmlschema/#sensor" xmlns:xacro="http://ros.org/wiki/xacro" xmlns:xi="http://www.w3.org/2001/XInclude">
  <link name="root">
    <visual>
      <origin rpy="0 0 0" xyz="0 0 0"/>
      <geometry>
        <box size="0 0 0"/>
      </geometry>
    </visual>
    <collision>
      <origin rpy="0 0 0" xyz="0 0 0"/>
      <geometry>
        <box size="0 0 0"/>
      </geometry>
    </collision>
  </link>
  <link name="mico_link_base">
    <visual>
      <geometry>
        <mesh filename="package://mico_description/meshes/mico_link_base.dae"/>
      </geometry>
      <material name="carbon_fiber">
        <color rgba="0.7922 0.8196 0.9333 1"/>
      </material>
    </visual>
    <collision>
      <geometry>
        <mesh filename="package://mico_description/meshes/mico_link_base.dae"/>
      </geometry>
    </collision>
  </link>
  <joint name="mico_joint_base" type="fixed">
    <parent link="root"/>
    <child link="mico_link_base"/>
    <axis xyz="0 0 0"/>
    <origin rpy="0 0 0" xyz="0 0 0"/>
    <limit effort="30" lower="-6.28318530718" upper="6.28318530718" velocity="5"/>
  </joint>
  <link name="mico_link_1">
    <visual>
      <geometry>
        <mesh filename="package://mico_description/meshes/mico_link_1.dae"/>
      </geometry>
      <material name="carbon_fiber">
        <color rgba="0.7922 0.8196 0.9333 1"/>
      </material>
    </visual>
    <collision>
      <geometry>
        <mesh filename="package://mico_description/meshes/mico_link_1.dae"/>
      </geometry>
    </collision>
  </link>
  <joint name="mico_joint_1" type="continuous">
    <parent link="mico_link_base"/>
    <child link="mico_link_1"/>
    <axis xyz="0 0 1"/>
    <origin rpy="3.14159265359 0 0" xyz="0 0 0.1535"/>
    <limit effort="30" lower="-6.28318530718" upper="6.28318530718" velocity="5"/>
  </joint>
  <link name="mico_link_2">
    <visual>
      <geometry>
        <mesh filename="package://mico_description/meshes/mico_link_2.dae"/>
      </geometry>
      <material name="carbon_fiber">
        <color rgba="0.7922 0.8196 0.9333 1"/>
      </material>
    </visual>
    <collision>
      <geometry>
        <mesh filename="package://mico_description/meshes/mico_link_2.dae"/>
      </geometry>
    </collision>
  </link>
  <joint name="mico_joint_2" type="revolute">
    <parent link="mico_link_1"/>
    <child link="mico_link_2"/>
    <axis xyz="0 0 1"/>
    <origin rpy="-1.57079632679 -1.57079632679 0" xyz="0 0 -0.1185"/>
    <limit effort="30" lower="0" upper="6.28318530718" velocity="5"/>
  </joint>
  <link name="mico_link_3">
    <visual>
      <geometry>
        <mesh filename="package://mico_description/meshes/mico_link_3.dae"/>
      </geometry>
      <material name="carbon_fiber">
        <color rgba="0.7922 0.8196 0.9333 1"/>
      </material>
    </visual>
    <collision>
      <geometry>
        <mesh filename="package://mico_description/meshes/mico_link_3.dae"/>
      </geometry>
    </collision>
  </link>
  <joint name="mico_joint_3" type="revolute">
    <parent link="mico_link_2"/>
    <child link="mico_link_3"/>
    <axis xyz="0 0 1"/>
    <origin rpy="3.14159265359 0 3.14159265359" xyz="0.29 0 0"/>
    <limit effort="30" lower="0" upper="6.28318530718" velocity="5"/>
  </joint>
  <link name="mico_link_4">
    <visual>
      <geometry>
        <mesh filename="package://mico_description/meshes/mico_link_4_5.dae"/>
      </geometry>
      <material name="carbon_fiber">
        <color rgba="0.7922 0.8196 0.9333 1"/>
      </material>
    </visual>
    <collision>
      <geometry>
        <mesh filename="package://mico_description/meshes/mico_link_4_5.dae"/>
      </geometry>
    </collision>
  </link>
  <joint name="mico_joint_4" type="continuous">
    <parent link="mico_link_3"/>
    <child link="mico_link_4"/>
    <axis xyz="0 0 1"/>
    <origin rpy="0 -1.57079632679 0" xyz="0.123 0 -0.00845"/>
    <limit effort="30" lower="-6.28318530718" upper="6.28318530718" velocity="5"/>
  </joint>
  <link name="mico_link_5">
    <visual>
      <geometry>
        <mesh filename="package://mico_description/meshes/mico_link_4_5.dae"/>
      </geometry>
      <material name="carbon_fiber">
        <color rgba="0.7922 0.8196 0.9333 1"/>
      </material>
    </visual>
    <collision>
      <geometry>
        <mesh filename="package://mico_description/meshes/mico_link_4_5.dae"/>
      </geometry>
    </collision>
  </link>
  <joint name="mico_joint_5" type="continuous">
    <parent link="mico_link_4"/>
    <child link="mico_link_5"/>
    <axis xyz="0 0 1"/>
    <origin rpy="0 1.0471975512 3.14159265359" xyz="0.03700 0 -0.06408"/>
    <limit effort="30" lower="-6.28318530718" upper="6.28318530718" velocity="5"/>
  </joint>
  <link name="mico_link_hand">
    <visual>
      <geometry>
        <mesh filename="package://mico_description/meshes/mico_link_hand.dae"/>
      </geometry>
      <material name="carbon_fiber">
        <color rgba="0.7922 0.8196 0.9333 1"/>
      </material>
    </visual>
    <collision>
      <geometry>
        <mesh filename="package://mico_description/meshes/mico_link_hand.dae"/>
      </geometry>
    </collision>
  </link>
  <joint name="mico_joint_6" type="continuous">
    <parent link="mico_link_5"/>
    <child link="mico_link_hand"/>
    <axis xyz="0 0 1"/>
    <origin rpy="0 1.0471975512 3.14159265359" xyz="0.03700 0 -0.06408"/>
    <limit effort="30" lower="-6.28318530718" upper="6.28318530718" velocity="5"/>
  </joint>
  <link name="mico_large_ring_cover_1">
    <visual>
      <geometry>
        <mesh filename="package://mico_description/meshes/mico_large_ring_cover.dae" scale="0.0254 0.0254 0.0254"/>
      </geometry>
      <material name="carbon_fiber">
        <color rgba="0.7922 0.8196 0.9333 1"/>
      </material>
    </visual>
    <collision>
      <geometry>
        <mesh filename="package://mico_description/meshes/mico_large_ring_cover.dae" scale="0.0254 0.0254 0.0254"/>
      </geometry>
    </collision>
  </link>
  <joint name="mico_large_ring_cover_1_joint" type="fixed">
    <parent link="mico_link_base"/>
    <child link="mico_large_ring_cover_1"/>
    <axis xyz="0 0 1"/>
    <origin rpy="3.14159265359 0 0" xyz="0 0 0.1535"/>
    <limit effort="30" lower="-6.28318530718" upper="6.28318530718" velocity="5"/>
  </joint>
  <link name="mico_large_ring_cover_2">
    <visual>
      <geometry>
        <mesh filename="package://mico_description/meshes/mico_large_ring_cover.dae" scale="0.0254 0.0254 0.0254"/>
      </geometry>
      <material name="carbon_fiber">
        <color rgba="0.7922 0.8196 0.9333 1"/>
      </material>
    </visual>
    <collision>
      <geometry>
        <mesh filename="package://mico_description/meshes/mico_large_ring_cover.dae" scale="0.0254 0.0254 0.0254"/>
      </geometry>
    </collision>
  </link>
  <joint name="mico_large_ring_cover_2_joint" type="fixed">
    <parent link="mico_link_1"/>
    <child link="mico_large_ring_cover_2"/>
    <axis xyz="0 0 1"/>
    <origin rpy="-1.57079632679 -1.57079632679 0" xyz="0 0 -0.1185"/>
    <limit effort="30" lower="0" upper="6.28318530718" velocity="5"/>
  </joint>
  <link name="mico_large_ring_cover_3">
    <visual>
      <geometry>
        <mesh filename="package://mico_description/meshes/mico_large_ring_cover.dae" scale="0.0254 0.0254 0.0254"/>
      </geometry>
      <material name="carbon_fiber">
        <color rgba="0.7922 0.8196 0.9333 1"/>
      </material>
    </visual>
    <collision>
      <geometry>
        <mesh filename="package://mico_description/meshes/mico_large_ring_cover.dae" scale="0.0254 0.0254 0.0254"/>
      </geometry>
    </collision>
  </link>
  <joint name="mico_large_ring_cover_3_joint" type="fixed">
    <parent link="mico_link_2"/>
    <child link="mico_large_ring_cover_3"/>
    <axis xyz="0 0 1"/>
    <origin rpy="3.14159265359 0 3.14159265359" xyz="0.29 0 0"/>
    <limit effort="30" lower="0" upper="6.28318530718" velocity="5"/>
  </joint>
  <link name="mico_small_ring_cover_1">
    <visual>
      <geometry>
        <mesh filename="package://mico_description/meshes/mico_small_ring_cover.dae" scale="0.0254 0.0254 0.0254"/>
      </geometry>
      <material name="carbon_fiber">
        <color rgba="0.7922 0.8196 0.9333 1"/>
      </material>
    </visual>
    <collision>
      <geometry>
        <mesh filename="package://mico_description/meshes/mico_small_ring_cover.dae" scale="0.0254 0.0254 0.0254"/>
      </geometry>
    </collision>
  </link>
  <joint name="mico_large_ring_cover_4_joint" type="fixed">
    <parent link="mico_link_3"/>
    <child link="mico_small_ring_cover_1"/>
    <axis xyz="0 0 1"/>
    <origin rpy="0 -1.57079632679 0" xyz="0.123 0 -0.00845"/>
    <limit effort="30" lower="-6.28318530718" upper="6.28318530718" velocity="5"/>
  </joint>
  <link name="mico_small_ring_cover_2">
    <visual>
      <geometry>
        <mesh filename="package://mico_description/meshes/mico_small_ring_cover.dae" scale="0.0254 0.0254 0.0254"/>
      </geometry>
      <material name="carbon_fiber">
        <color rgba="0.7922 0.8196 0.9333 1"/>
      </material>
    </visual>
    <collision>
      <geometry>
        <mesh filename="package://mico_description/meshes/mico_small_ring_cover.dae" scale="0.0254 0.0254 0.0254"/>
      </geometry>
    </collision>
  </link>
  <joint name="mico_large_ring_cover_5_joint" type="fixed">
    <parent link="mico_link_4"/>
    <child link="mico_small_ring_cover_2"/>
    <axis xyz="0 0 1"/>
    <origin rpy="0 1.0471975512 3.14159265359" xyz="0.03700 0 -0.06408"/>
    <limit effort="30" lower="-6.28318530718" upper="6.28318530718" velocity="5"/>
  </joint>
  <link name="mico_small_ring_cover_3">
    <visual>
      <geometry>
        <mesh filename="package://mico_description/meshes/mico_small_ring_cover.dae" scale="0.0254 0.0254 0.0254"/>
      </geometry>
      <material name="carbon_fiber">
        <color rgba="0.7922 0.8196 0.9333 1"/>
      </material>
    </visual>
    <collision>
      <geometry>
        <mesh filename="package://mico_description/meshes/mico_small_ring_cover.dae" scale="0.0254 0.0254 0.0254"/>
      </geometry>
    </collision>
  </link>
  <joint name="mico_large_ring_cover_6_joint" type="fixed">
    <parent link="mico_link_5"/>
    <child link="mico_small_ring_cover_3"/>
    <axis xyz="0 0 1"/>
    <origin rpy="0 1.0471975512 3.14159265359" xyz="0.03700 0 -0.06408"/>
    <limit effort="30" lower="-6.28318530718" upper="6.28318530718" velocity="5"/>
  </joint>
  <link name="mico_link_finger_1">
    <visual>
      <geometry>
        <mesh filename="package://mico_description/meshes/mico_link_finger.dae" scale="0.0254 0.0254 0.0254"/>
      </geometry>
      <material name="carbon_fiber">
        <color rgba="0.7922 0.8196 0.9333 1"/>
      </material>
    </visual>
    <collision>
      <geometry>
        <mesh filename="package://mico_description/meshes/mico_link_finger.dae" scale="0.0254 0.0254 0.0254"/>
      </geometry>
    </collision>
  </link>
  <joint name="mico_joint_finger_1" type="revolute">
    <parent link="mico_link_hand"/>
    <child link="mico_link_finger_1"/>
    <axis xyz="0 0 1"/>
    <origin rpy="-1.5707 1.1 3.1416" xyz="-0.03095 -0.0025 -0.115"/>
    <limit effort="30" lower="0" upper="0.698131700798" velocity="5"/>
  </joint>
  <link name="mico_link_finger_2">
    <visual>
      <geometry>
        <mesh filename="package://mico_description/meshes/mico_link_finger.dae" scale="0.0254 0.0254 0.0254"/>
      </geometry>
      <material name="carbon_fiber">
        <color rgba="0.7922 0.8196 0.9333 1"/>
      </material>
    </visual>
    <collision>
      <geometry>
        <mesh filename="package://mico_description/meshes/mico_link_finger.dae" scale="0.0254 0.0254 0.0254"/>
      </geometry>
    </collision>
  </link>
  <joint name="mico_joint_finger_2" type="revolute">
    <parent link="mico_link_hand"/>
    <child link="mico_link_finger_2"/>
    <axis xyz="0 0 1"/>
    <origin rpy="-1.5707 1.1 0.0" xyz="0.03095 -0.0025 -0.115"/>
    <limit effort="30" lower="0" upper="0.698131700798" velocity="5"/>
    <mimic joint="mico_joint_finger_1"/>
  </joint>
  <link name="mico_link_finger_tip_1">
    <visual>
      <geometry>
        <mesh filename="package://mico_description/meshes/mico_link_finger_tip.dae" scale="0.0254 0.0254 0.0254"/>
      </geometry>
      <material name="carbon_fiber">
        <color rgba="0.7922 0.8196 0.9333 1"/>
      </material>
    </visual>
    <collision>
      <geometry>
        <mesh filename="package://mico_description/meshes/mico_link_finger_tip.dae" scale="0.0254 0.0254 0.0254"/>
      </geometry>
    </collision>
  </link>
  <joint name="mico_joint_finger_tip_1" type="fixed">
    <parent link="mico_link_finger_1"/>
    <child link="mico_link_finger_tip_1"/>
    <axis xyz="0 0 1"/>
    <origin rpy="0 0 0" xyz="0.044094 -0.0029 0"/>
    <limit effort="30" lower="0" upper="0.698131700798" velocity="5"/>
  </joint>
  <link name="mico_link_finger_tip_2">
    <visual>
      <geometry>
        <mesh filename="package://mico_description/meshes/mico_link_finger_tip.dae" scale="0.0254 0.0254 0.0254"/>
      </geometry>
      <material name="carbon_fiber">
        <color rgba="0.7922 0.8196 0.9333 1"/>
      </material>
    </visual>
    <collision>
      <geometry>
        <mesh filename="package://mico_description/meshes/mico_link_finger_tip.dae" scale="0.0254 0.0254 0.0254"/>
      </geometry>
    </collision>
  </link>
  <joint name="mico_joint_finger_tip_2" type="fixed">
    <parent link="mico_link_finger_2"/>
    <child link="mico_link_finger_tip_2"/>
    <axis xyz="0 0 1"/>
    <origin rpy="0 0 0" xyz="0.044094 -0.0029 0"/>
    <limit effort="30" lower="0" upper="0.698131700798" velocity="5"/>
    <mimic joint="mico_joint_finger_tip_1"/>
  </joint>
  <link name="mico_link_endeffector"/>
  <joint name="mico_endeffector_joint" type="fixed">
    <parent link="mico_link_hand"/>
    <child link="mico_link_endeffector"/>
    <axis xyz="0 0 1"/>
    <origin rpy="0 0 0" xyz="0 0 -0.16"/>
    <limit effort="30" lower="-6.28318530718" upper="6.28318530718" velocity="5"/>
  </joint>
  <joint name="camera_frame_joint" type="fixed">
    <parent link="root"/>
    <child link="camera_link"/>
    <axis xyz="0 0 1"/>
    <origin rpy="0 0 0" xyz="-1.0 0 1.0"/>
  </joint>
  <link name="camera_link"/>
  <joint name="camera_rgb_optical_frame_joint" type="fixed">
    <origin rpy="-1.57079632679 0.0 -1.57079632679" xyz="0 0 0"/>
    <parent link="camera_link"/>
    <child link="camera_rgb_optical_frame"/>
  </joint>
  <link name="camera_rgb_optical_frame"/>
  <joint name="camera_depth_optical_frame_joint" type="fixed">
    <origin rpy="-1.57079632679 0.0 -1.57079632679" xyz="0 0 0"/>
    <parent link="camera_link"/>
    <child link="camera_depth_optical_frame"/>
  </joint>
  <link name="camera_depth_optical_frame"/>
</robot>
