<?xml version="1.0" ?>
<!-- =================================================================================== -->
<!-- |    This document was autogenerated by xacro from phantomx_reactor_arm_wrist.urdf.xacro | -->
<!-- |    EDITING THIS FILE BY HAND IS NOT RECOMMENDED                                 | -->
<!-- =================================================================================== -->
<robot name="phantomx_reactor_arm" xmlns:xacro="http://www.ros.org/wiki/xacro">
  <link name="base_footprint">
    <visual>
      <origin rpy="0 0 0" xyz="0 0 0"/>
      <geometry>
        <box size="0.001 0.001 0.001"/>
      </geometry>
    </visual>
  </link>
  <!-- ARM BASE JOINT -->
  <joint name="base_joint" type="fixed">
    <origin rpy="0 0 0" xyz="0 0 0"/>
    <parent link="base_footprint"/>
    <child link="base_link"/>
  </joint>
  <link name="base_link">
    <inertial>
      <origin rpy="0 0 0" xyz="-3.9657E-09 2.0144E-09 0.04262"/>
      <mass value="0.33742"/>
      <inertia ixx="0.0011303" ixy="2.3398E-15" ixz="5.3844E-11" iyy="0.0011303" iyz="-2.735E-11" izz="0.0016747"/>
    </inertial>
    <visual>
      <origin rpy="0 0 0" xyz="0 0 0"/>
      <geometry>
        <mesh filename="package://phantomx_reactor_arm_description/meshes/base_link.STL"/>
      </geometry>
      <material name="">
        <color rgba="0.25098 0.25098 0.25098 1"/>
      </material>
    </visual>
    <collision>
      <origin rpy="0 0 0" xyz="0 0 0"/>
      <geometry>
        <mesh filename="package://phantomx_reactor_arm_description/meshes/base_link_hull.STL"/>
      </geometry>
    </collision>
  </link>
  <!-- SHOULDER YAW -->
  <joint name="shoulder_yaw_joint" type="revolute">
    <origin rpy="0 0 0" xyz="0 0 0.081"/>
    <!--origin xyz="0 0 0.081" rpy="0 0 0" /-->
    <parent link="base_link"/>
    <child link="shoulder_link"/>
    <axis xyz="0 0 1"/>
    <limit effort="1.5" lower="-3.141593" upper="3.141593" velocity="6.178465545"/>
  </joint>
  <link name="shoulder_link">
    <inertial>
      <origin rpy="0 0 0" xyz="5.5296E-07 0.00048339 0.0026355"/>
      <mass value="0.069055"/>
      <inertia ixx="7.786E-05" ixy="4.5909E-11" ixz="-6.4873E-11" iyy="4.1745E-05" iyz="2.8244E-07" izz="0.0001073"/>
    </inertial>
    <visual>
      <origin rpy="0 0 0" xyz="0 0 0"/>
      <geometry>
        <mesh filename="package://phantomx_reactor_arm_description/meshes/shoulder_link.STL"/>
      </geometry>
      <material name="">
        <color rgba="0.25098 0.25098 0.25098 1"/>
      </material>
    </visual>
    <collision>
      <origin rpy="0 0 0" xyz="0 0 0"/>
      <geometry>
        <mesh filename="package://phantomx_reactor_arm_description/meshes/shoulder_link_hull.STL"/>
      </geometry>
    </collision>
  </link>
  <!-- SHOULDER PITCH -->
  <joint name="shoulder_pitch_joint" type="revolute">
    <origin rpy="1.5707965 0 0" xyz="0 0 0.0265"/>
    <parent link="shoulder_link"/>
    <child link="bicep_link"/>
    <axis xyz="0 0 1"/>
    <limit effort="3.0" lower="-1.5707965" upper="1.5707965" velocity="6.178465545"/>
  </joint>
  <link name="bicep_link">
    <inertial>
      <origin rpy="-1.5707965 0 -1.5707965" xyz="-0.079312 0.00175 0.0073486"/>
      <mass value="0.29331"/>
      <inertia ixx="0.00040741" ixy="-1.1578E-09" ixz="-0.00014106" iyy="0.0010604" iyz="1.1578E-09" izz="0.0012838"/>
    </inertial>
    <visual>
      <origin rpy="-1.5707965 0 -1.5707965" xyz="0 0 0"/>
      <geometry>
        <mesh filename="package://phantomx_reactor_arm_description/meshes/bicep_link.STL"/>
      </geometry>
      <material name="">
        <color rgba="0.25098 0.25098 0.25098 1"/>
      </material>
    </visual>
    <collision>
      <origin rpy="-1.5707965 0 -1.5707965" xyz="0 0 0"/>
      <geometry>
        <mesh filename="package://phantomx_reactor_arm_description/meshes/bicep_link_hull.STL"/>
      </geometry>
    </collision>
  </link>
  <!-- ELBOW PITCH-->
  <joint name="elbow_pitch_joint" type="revolute">
    <origin rpy="-1.5707965 0 0" xyz="0.0385 0.1445 0"/>
    <parent link="bicep_link"/>
    <child link="forearm_link"/>
    <axis xyz="0 1 0"/>
    <limit effort="3.0" lower="-1.5707965" upper="1.5707965" velocity="6.178465545"/>
  </joint>
  <link name="forearm_link">
    <inertial>
      <origin rpy="0 0 0" xyz="0.0851888339312843 0.00136288621406396 -0.000141576344087929"/>
      <mass value="0.138705662443181"/>
      <inertia ixx="9.73074886909647E-05" ixy="-2.7259894490049E-06" ixz="8.2757647661483E-07" iyy="0.000291190570207828" iyz="-7.99252279784603E-09" izz="0.000367301178753318"/>
    </inertial>
    <visual>
      <origin rpy="0 0 0" xyz="0 0 0"/>
      <geometry>
        <mesh filename="package://phantomx_reactor_arm_description/meshes/forearm_link.STL"/>
      </geometry>
      <material name="">
        <color rgba="0.25098 0.25098 0.25098 1"/>
      </material>
    </visual>
    <collision>
      <origin rpy="0 0 0" xyz="0 0 0"/>
      <geometry>
        <mesh filename="package://phantomx_reactor_arm_description/meshes/forearm_link_hull.STL"/>
      </geometry>
    </collision>
  </link>
  <!-- WRIST PITCH-->
  <joint name="wrist_pitch_joint" type="revolute">
    <origin rpy="0 0 0" xyz="0.1535 0 0"/>
    <parent link="forearm_link"/>
    <child link="wrist_1_link"/>
    <axis xyz="0 1 0"/>
    <limit effort="1.5" lower="-1.7" upper="1.9" velocity="6.178465545"/>
  </joint>
  <link name="wrist_1_link">
    <inertial>
      <origin rpy="0 0 0" xyz="0.0426453655090486 0.0017494960392062 0.00984847105297723"/>
      <mass value="0.0605067986491363"/>
      <inertia ixx="1.78648656995261E-05" ixy="1.11621731933541E-10" ixz="3.58888722407994E-06" iyy="2.8352036542644E-05" iyz="-2.18072661043818E-10" izz="2.38673851634115E-05"/>
    </inertial>
    <visual>
      <origin rpy="0 0 0" xyz="0 0 0"/>
      <geometry>
        <mesh filename="package://phantomx_reactor_arm_description/meshes/wrist_1.STL"/>
      </geometry>
      <material name="">
        <color rgba="0.25098 0.25098 0.25098 1"/>
      </material>
    </visual>
    <collision>
      <origin rpy="0 0 0" xyz="0 0 0"/>
      <geometry>
        <mesh filename="package://phantomx_reactor_arm_description/meshes/wrist_1_hull.STL"/>
      </geometry>
    </collision>
  </link>
  <!-- WRIST ROLL -->
  <joint name="wrist_roll_joint" type="revolute">
    <origin rpy="0 0 0" xyz="0.071 0.00175 0"/>
    <parent link="wrist_1_link"/>
    <child link="wrist_2_link"/>
    <axis xyz="1 0 0"/>
    <limit effort="1.5" lower="-3.141593" upper="3.141593" velocity="6.178465545"/>
  </joint>
  <link name="wrist_2_link">
    <inertial>
      <origin rpy="0 0 0" xyz="0.022349 -5.4754E-07 0.0089164"/>
      <mass value="0.055706"/>
      <inertia ixx="1.5957E-05" ixy="2.0952E-10" ixz="3.3629E-06" iyy="2.1196E-05" iyz="-2.4643E-10" izz="1.4482E-05"/>
    </inertial>
    <visual>
      <origin rpy="0 0 0" xyz="0 0 0"/>
      <geometry>
        <mesh filename="package://phantomx_reactor_arm_description/meshes/wrist_2.STL"/>
      </geometry>
      <material name="">
        <color rgba="0.25098 0.25098 0.25098 1"/>
      </material>
    </visual>
    <collision>
      <origin rpy="0 0 0" xyz="0 0 0"/>
      <geometry>
        <mesh filename="package://phantomx_reactor_arm_description/meshes/wrist_2_hull.STL"/>
      </geometry>
    </collision>
  </link>
  <!-- GRIPPER -->
  <joint name="gripper_guide_joint" type="fixed">
    <origin rpy="0 0 0" xyz="0.05 0.00 0"/>
    <parent link="wrist_2_link"/>
    <child link="gripper_guide_link"/>
    <axis xyz="0 0 1"/>
    <limit effort="1.5" lower="0" upper="1.57" velocity="6.178465545"/>
  </joint>
  <link name="gripper_guide_link">
    <inertial>
      <origin rpy="0 0 0" xyz="0.0091884 -7.3309E-13 -3.4513E-05"/>
      <mass value="0.02487"/>
      <inertia ixx="1.5997E-05" ixy="1.6551E-16" ixz="8.3911E-09" iyy="7.3918E-06" iyz="-2.7145E-16" izz="1.5931E-05"/>
    </inertial>
    <visual>
      <origin rpy="1.57 3.14 1.57" xyz="0 0 0"/>
      <geometry>
        <mesh filename="package://phantomx_reactor_arm_description/meshes/Guide_Rail_Fixed_Centered.stl" scale="0.01 0.01 0.01"/>
      </geometry>
      <material name="">
        <color rgba="0.25098 0.25098 0.25098 1"/>
      </material>
    </visual>
    <collision>
      <origin rpy="1.57 3.14 1.57" xyz="0 0 0"/>
      <geometry>
        <mesh filename="package://phantomx_reactor_arm_description/meshes/Guide_Rail_Fixed_Centered.stl" scale="0.01 0.01 0.01"/>
      </geometry>
    </collision>
  </link>
  <joint name="gripper_revolute_joint" type="revolute">
    <origin rpy="0 1.5707965 0" xyz="0 0 0"/>
    <parent link="gripper_guide_link"/>
    <child link="gripper_aux_link"/>
    <axis xyz="0 0 1"/>
    <limit effort="0" lower="-3.141593" upper="3.141593" velocity="0.5"/>
  </joint>
  <link name="gripper_aux_link"> 
		</link>
  <joint name="gripper_right_joint" type="prismatic">
    <origin rpy="0 0 0" xyz="0.0202 0 0"/>
    <parent link="gripper_guide_link"/>
    <child link="gripper_right_link"/>
    <axis xyz="0 1 0"/>
    <limit effort="1.5" lower="0.03" upper="0.0" velocity="6.178465545"/>
  </joint>
  <link name="gripper_right_link">
    <visual>
      <origin rpy="-1.57 -1.57 0" xyz="0 0.010 0"/>
      <geometry>
        <mesh filename="package://phantomx_reactor_arm_description/meshes/Gripper_Hand_Fixed_Centered.stl" scale="0.01 0.01 0.01"/>
      </geometry>
      <material name="">
        <color rgba="0.25098 0.25098 0.25098 1"/>
      </material>
    </visual>
    <collision>
      <origin rpy="-1.57 -1.57 0" xyz="0 0.010 0"/>
      <geometry>
        <mesh filename="package://phantomx_reactor_arm_description/meshes/Gripper_Hand_Fixed_Centered.stl" scale="0.01 0.01 0.01"/>
      </geometry>
    </collision>
  </link>
  <joint name="gripper_left_joint" type="prismatic">
    <origin rpy="0 0 0" xyz="0.0202 0 0"/>
    <parent link="gripper_guide_link"/>
    <child link="gripper_left_link"/>
    <axis xyz="0 1 0"/>
    <limit effort="1.5" lower="-1.9" upper="0" velocity="6.178465545"/>
    <mimic joint="gripper_right_joint" multiplier="-1.0"/>
  </joint>
  <link name="gripper_left_link">
    <visual>
      <origin rpy="1.57 1.57 0" xyz="0 -0.010 0"/>
      <geometry>
        <mesh filename="package://phantomx_reactor_arm_description/meshes/Gripper_Hand_Fixed_Centered.stl" scale="0.01 0.01 0.01"/>
      </geometry>
      <material name="">
        <color rgba="0.25098 0.25098 0.25098 1"/>
      </material>
    </visual>
    <collision>
      <origin rpy="1.57 1.57 0" xyz="0 -0.010 0"/>
      <geometry>
        <mesh filename="package://phantomx_reactor_arm_description/meshes/Gripper_Hand_Fixed_Centered.stl" scale="0.01 0.01 0.01"/>
      </geometry>
    </collision>
  </link>
</robot>

