<?xml version="1.0" ?>
<!-- =================================================================================== -->
<!-- |    This document was autogenerated by xacro from j2s7s300_standalone.xacro      | -->
<!-- |    EDITING THIS FILE BY HAND IS NOT RECOMMENDED                                 | -->
<!-- =================================================================================== -->
<!-- j2s7s300 refers to jaco v2 7DOF spherical 3fingers -->
<robot name="j2s7s300" xmlns:body="http://playerstage.sourceforge.net/gazebo/xmlschema/#body" xmlns:controller="http://playerstage.sourceforge.net/gazebo/xmlschema/#controller" xmlns:gazebo="http://playerstage.sourceforge.net/gazebo/xmlschema/#gz" xmlns:geom="http://playerstage.sourceforge.net/gazebo/xmlschema/#geom" xmlns:interface="http://playerstage.sourceforge.net/gazebo/xmlschema/#interface" xmlns:joint="http://playerstage.sourceforge.net/gazebo/xmlschema/#joint" xmlns:model="http://playerstage.sourceforge.net/gazebo/xmlschema/#model" xmlns:physics="http://playerstage.sourceforge.net/gazebo/xmlschema/#physics" xmlns:renderable="http://playerstage.sourceforge.net/gazebo/xmlschema/#renderable" xmlns:rendering="http://playerstage.sourceforge.net/gazebo/xmlschema/#rendering" xmlns:sensor="http://playerstage.sourceforge.net/gazebo/xmlschema/#sensor" xmlns:xacro="http://ros.org/wiki/xacro" xmlns:xi="http://www.w3.org/2001/XInclude">
  <link name="root_a">
    <visual>
      <origin rpy="0 0 0" xyz="0 0 0"/>
      <geometry>
        <box size="0 0 0"/>
      </geometry>
      <!--<material name="Black" /> -->
    </visual>
    <collision>
      <origin rpy="0 0 0" xyz="0 0 0"/>
      <geometry>
        <box size="0 0 0"/>
      </geometry>
    </collision>
  </link>
  <!-- for gazebo -->
  <link name="world"/>
  <joint name="connect_root_and_world_a" type="fixed">
    <child link="root_a"/>
    <parent link="world"/>
    <origin rpy="0 0 0" xyz="0 0 0"/>
  </joint>
  <!-- ros_control plugin -->
  <gazebo>
    <plugin filename="libgazebo_ros_control.so" name="gazebo_ros_control">
      <robotNamespace>j2s7s300</robotNamespace>
      <robotSimType>gazebo_ros_control/DefaultRobotHWSim</robotSimType>
    </plugin>
  </gazebo>
  <link name="j2s7s300_link_base_a">
    <visual>
      <geometry>
        <mesh filename="package://kinova_description/meshes/base.dae"/>
      </geometry>
      <material name="carbon_fiber">
        <color rgba="0.792156862745098 0.819607843137255 0.933333333333333 1"/>
      </material>
    </visual>
    <collision>
      <geometry>
        <mesh filename="package://kinova_description/meshes/base.dae"/>
      </geometry>
    </collision>
    <inertial>
      <mass value="0.46784"/>
      <origin rpy="0 0 0" xyz="0 0 0.1255"/>
      <inertia ixx="0.000951270861568" ixy="0" ixz="0" iyy="0.000951270861568" iyz="0" izz="0.000374272"/>
    </inertial>
  </link>
  <joint name="j2s7s300_joint_base_a" type="fixed">
    <parent link="root_a"/>
    <child link="j2s7s300_link_base_a"/>
    <axis xyz="0 0 0"/>
    <limit effort="2000" lower="0" upper="0" velocity="1"/>
    <origin rpy="0 0 0" xyz="0 0 0"/>
    <dynamics damping="0.0" friction="0.0"/>
  </joint>
  <link name="j2s7s300_link_1_a">
    <visual>
      <geometry>
        <mesh filename="package://kinova_description/meshes/shoulder.dae"/>
      </geometry>
      <material name="carbon_fiber">
        <color rgba="0.792156862745098 0.819607843137255 0.933333333333333 1"/>
      </material>
    </visual>
    <visual>
      <geometry>
        <mesh filename="package://kinova_description/meshes/ring_big.STL"/>
      </geometry>
    </visual>
    <collision>
      <geometry>
        <mesh filename="package://kinova_description/meshes/shoulder.dae"/>
      </geometry>
    </collision>
    <inertial>
      <mass value="0.7477"/>
      <origin xyz="0 -0.002 -0.0605"/>
      <inertia ixx="0.00152031725204" ixy="0" ixz="0" iyy="0.00152031725204" iyz="0" izz="0.00059816"/>
    </inertial>
  </link>
  <joint name="j2s7s300_joint_1_a" type="continuous">
    <parent link="j2s7s300_link_base_a"/>
    <child link="j2s7s300_link_1_a"/>
    <axis xyz="0 0 1"/>
    <limit effort="2000" lower="-6.28318530718" upper="6.28318530718" velocity="1"/>
    <origin rpy="0 3.14159265359 0" xyz="0 0 0.15675"/>
    <dynamics damping="0.0" friction="0.0"/>
  </joint>
  <transmission name="j2s7s300_joint_1_trans">
    <type>transmission_interface/SimpleTransmission</type>
    <joint name="j2s7s300_joint_1_a">
      <hardwareInterface>EffortJointInterface</hardwareInterface>
    </joint>
    <actuator name="j2s7s300_joint_1_actuator">
      <hardwareInterface>EffortJointInterface</hardwareInterface>
      <mechanicalReduction>160</mechanicalReduction>
    </actuator>
  </transmission>
  <link name="j2s7s300_link_2_a">
    <visual>
      <geometry>
        <mesh filename="package://kinova_description/meshes/arm_half_1.dae"/>
      </geometry>
      <material name="carbon_fiber">
        <color rgba="0.792156862745098 0.819607843137255 0.933333333333333 1"/>
      </material>
    </visual>
    <visual>
      <geometry>
        <mesh filename="package://kinova_description/meshes/ring_big.STL"/>
      </geometry>
    </visual>
    <collision>
      <geometry>
        <mesh filename="package://kinova_description/meshes/arm_half_1.dae"/>
      </geometry>
    </collision>
    <inertial>
      <mass value="0.8447"/>
      <origin xyz="0 -0.103563213 0"/>
      <inertia ixx="0.00247073761701" ixy="0" ixz="0" iyy="0.000380115" iyz="0" izz="0.00247073761701"/>
    </inertial>
  </link>
  <joint name="j2s7s300_joint_2_a" type="revolute">
    <parent link="j2s7s300_link_1_a"/>
    <child link="j2s7s300_link_2_a"/>
    <axis xyz="0 0 1"/>
    <limit effort="2000" lower="0.820304748437" upper="5.46288055874" velocity="1"/>
    <origin rpy="-1.57079632679 0 3.14159265359" xyz="0 0.0016 -0.11875"/>
    <dynamics damping="0.0" friction="0.0"/>
  </joint>
  <transmission name="j2s7s300_joint_2_trans">
    <type>transmission_interface/SimpleTransmission</type>
    <joint name="j2s7s300_joint_2_a">
      <hardwareInterface>EffortJointInterface</hardwareInterface>
    </joint>
    <actuator name="j2s7s300_joint_2_actuator">
      <hardwareInterface>EffortJointInterface</hardwareInterface>
      <mechanicalReduction>160</mechanicalReduction>
    </actuator>
  </transmission>
  <link name="j2s7s300_link_3_a">
    <visual>
      <geometry>
        <mesh filename="package://kinova_description/meshes/arm_half_2.dae"/>
      </geometry>
      <material name="carbon_fiber">
        <color rgba="0.792156862745098 0.819607843137255 0.933333333333333 1"/>
      </material>
    </visual>
    <visual>
      <geometry>
        <mesh filename="package://kinova_description/meshes/ring_big.STL"/>
      </geometry>
    </visual>
    <collision>
      <geometry>
        <mesh filename="package://kinova_description/meshes/arm_half_2.dae"/>
      </geometry>
    </collision>
    <inertial>
      <mass value="0.8447"/>
      <origin xyz="0 0 -0.1022447445"/>
      <inertia ixx="0.00247073761701" ixy="0" ixz="0" iyy="0.00247073761701" iyz="0" izz="0.000380115"/>
    </inertial>
  </link>
  <joint name="j2s7s300_joint_3_a" type="continuous">
    <parent link="j2s7s300_link_2_a"/>
    <child link="j2s7s300_link_3_a"/>
    <axis xyz="0 0 1"/>
    <limit effort="2000" lower="-6.28318530718" upper="6.28318530718" velocity="1"/>
    <origin rpy="-1.57079632679 0 0" xyz="0 -0.205 0"/>
    <dynamics damping="0.0" friction="0.0"/>
  </joint>
  <transmission name="j2s7s300_joint_3_trans">
    <type>transmission_interface/SimpleTransmission</type>
    <joint name="j2s7s300_joint_3_a">
      <hardwareInterface>EffortJointInterface</hardwareInterface>
    </joint>
    <actuator name="j2s7s300_joint_3_actuator">
      <hardwareInterface>EffortJointInterface</hardwareInterface>
      <mechanicalReduction>160</mechanicalReduction>
    </actuator>
  </transmission>
  <link name="j2s7s300_link_4_a">
    <visual>
      <geometry>
        <mesh filename="package://kinova_description/meshes/forearm.dae"/>
      </geometry>
      <material name="carbon_fiber">
        <color rgba="0.792156862745098 0.819607843137255 0.933333333333333 1"/>
      </material>
    </visual>
    <visual>
      <geometry>
        <mesh filename="package://kinova_description/meshes/ring_small.STL"/>
      </geometry>
    </visual>
    <collision>
      <geometry>
        <mesh filename="package://kinova_description/meshes/forearm.dae"/>
      </geometry>
    </collision>
    <inertial>
      <mass value="0.6763"/>
      <origin xyz="0 0.081 -0.0086"/>
      <inertia ixx="0.00142022431908" ixy="0" ixz="0" iyy="0.000304335" iyz="0" izz="0.00142022431908"/>
    </inertial>
  </link>
  <joint name="j2s7s300_joint_4_a" type="revolute">
    <parent link="j2s7s300_link_3_a"/>
    <child link="j2s7s300_link_4_a"/>
    <axis xyz="0 0 1"/>
    <limit effort="2000" lower="0.523598775598" upper="5.75958653158" velocity="1"/>
    <origin rpy="1.57079632679 0 3.14159265359" xyz="0 0 -0.205"/>
    <dynamics damping="0.0" friction="0.0"/>
  </joint>
  <transmission name="j2s7s300_joint_4_trans">
    <type>transmission_interface/SimpleTransmission</type>
    <joint name="j2s7s300_joint_4_a">
      <hardwareInterface>EffortJointInterface</hardwareInterface>
    </joint>
    <actuator name="j2s7s300_joint_4_actuator">
      <hardwareInterface>EffortJointInterface</hardwareInterface>
      <mechanicalReduction>160</mechanicalReduction>
    </actuator>
  </transmission>
  <link name="j2s7s300_link_5_a">
    <visual>
      <geometry>
        <mesh filename="package://kinova_description/meshes/wrist_spherical_1.dae"/>
      </geometry>
      <material name="carbon_fiber">
        <color rgba="0.792156862745098 0.819607843137255 0.933333333333333 1"/>
      </material>
    </visual>
    <visual>
      <geometry>
        <mesh filename="package://kinova_description/meshes/ring_small.STL"/>
      </geometry>
    </visual>
    <collision>
      <geometry>
        <mesh filename="package://kinova_description/meshes/wrist_spherical_1.dae"/>
      </geometry>
    </collision>
    <inertial>
      <mass value="0.463"/>
      <origin xyz="0 0.0028848942 -0.0541932613"/>
      <inertia ixx="0.0004321316048" ixy="0" ixz="0" iyy="0.0004321316048" iyz="0" izz="9.26e-05"/>
    </inertial>
  </link>
  <joint name="j2s7s300_joint_5_a" type="continuous">
    <parent link="j2s7s300_link_4_a"/>
    <child link="j2s7s300_link_5_a"/>
    <axis xyz="0 0 1"/>
    <limit effort="2000" lower="-6.28318530718" upper="6.28318530718" velocity="1"/>
    <origin rpy="-1.57079632679 0 3.14159265359" xyz="0 0.2073 -0.0114"/>
    <dynamics damping="0.0" friction="0.0"/>
  </joint>
  <transmission name="j2s7s300_joint_5_trans">
    <type>transmission_interface/SimpleTransmission</type>
    <joint name="j2s7s300_joint_5_a">
      <hardwareInterface>EffortJointInterface</hardwareInterface>
    </joint>
    <actuator name="j2s7s300_joint_5_actuator">
      <hardwareInterface>EffortJointInterface</hardwareInterface>
      <mechanicalReduction>160</mechanicalReduction>
    </actuator>
  </transmission>
  <link name="j2s7s300_link_6_a">
    <visual>
      <geometry>
        <mesh filename="package://kinova_description/meshes/wrist_spherical_2.dae"/>
      </geometry>
      <material name="carbon_fiber">
        <color rgba="0.792156862745098 0.819607843137255 0.933333333333333 1"/>
      </material>
    </visual>
    <visual>
      <geometry>
        <mesh filename="package://kinova_description/meshes/ring_small.STL"/>
      </geometry>
    </visual>
    <collision>
      <geometry>
        <mesh filename="package://kinova_description/meshes/wrist_spherical_2.dae"/>
      </geometry>
    </collision>
    <inertial>
      <mass value="0.463"/>
      <origin xyz="0 0.0497208855 -0.0028562765"/>
      <inertia ixx="0.0004321316048" ixy="0" ixz="0" iyy="9.26e-05" iyz="0" izz="0.0004321316048"/>
    </inertial>
  </link>
  <joint name="j2s7s300_joint_6_a" type="revolute">
    <parent link="j2s7s300_link_5_a"/>
    <child link="j2s7s300_link_6_a"/>
    <axis xyz="0 0 1"/>
    <limit effort="2000" lower="1.1344640138" upper="5.14872129338" velocity="1"/>
    <origin rpy="1.57079632679 0 3.14159265359" xyz="0 0 -0.10375"/>
    <dynamics damping="0.0" friction="0.0"/>
  </joint>
  <transmission name="j2s7s300_joint_6_trans">
    <type>transmission_interface/SimpleTransmission</type>
    <joint name="j2s7s300_joint_6_a">
      <hardwareInterface>EffortJointInterface</hardwareInterface>
    </joint>
    <actuator name="j2s7s300_joint_6_actuator">
      <hardwareInterface>EffortJointInterface</hardwareInterface>
      <mechanicalReduction>160</mechanicalReduction>
    </actuator>
  </transmission>
  <link name="j2s7s300_link_7_a">
    <visual>
      <geometry>
        <mesh filename="package://kinova_description/meshes/hand_3finger.dae"/>
      </geometry>
      <material name="carbon_fiber">
        <color rgba="0.792156862745098 0.819607843137255 0.933333333333333 1"/>
      </material>
    </visual>
    <visual>
      <geometry>
        <mesh filename="package://kinova_description/meshes/ring_small.STL"/>
      </geometry>
    </visual>
    <collision>
      <geometry>
        <mesh filename="package://kinova_description/meshes/hand_3finger.dae"/>
      </geometry>
    </collision>
    <inertial>
      <mass value="0.727"/>
      <origin xyz="0 0 -0.06"/>
      <inertia ixx="0.0003453236187" ixy="0" ixz="0" iyy="0.0003453236187" iyz="0" izz="0.0005816"/>
    </inertial>
  </link>
  <joint name="j2s7s300_joint_7_a" type="continuous">
    <parent link="j2s7s300_link_6_a"/>
    <child link="j2s7s300_link_7_a"/>
    <axis xyz="0 0 1"/>
    <limit effort="2000" lower="-6.28318530718" upper="6.28318530718" velocity="1"/>
    <origin rpy="-1.57079632679 0 3.14159265359" xyz="0 0.10375 0"/>
    <dynamics damping="0.0" friction="0.0"/>
  </joint>
  <transmission name="j2s7s300_joint_7_trans">
    <type>transmission_interface/SimpleTransmission</type>
    <joint name="j2s7s300_joint_7_a">
      <hardwareInterface>EffortJointInterface</hardwareInterface>
    </joint>
    <actuator name="j2s7s300_joint_7_actuator">
      <hardwareInterface>EffortJointInterface</hardwareInterface>
      <mechanicalReduction>160</mechanicalReduction>
    </actuator>
  </transmission>
  <link name="j2s7s300_end_effector_a">
    <visual>
      <geometry>
        <box size="0 0 0"/>
      </geometry>
    </visual>
    <collision>
      <geometry>
        <box size="0 0 0"/>
      </geometry>
    </collision>
  </link>
  <joint name="j2s7s300_joint_end_effector_a" type="fixed">
    <parent link="j2s7s300_link_7_a"/>
    <child link="j2s7s300_end_effector_a"/>
    <axis xyz="0 0 0"/>
    <limit effort="2000" lower="0" upper="0" velocity="1"/>
    <origin rpy="3.14159265359 0 0" xyz="0 0 -0.1600"/>
  </joint>
  <link name="j2s7s300_link_finger_1_a">
    <visual>
      <geometry>
        <mesh filename="package://kinova_description/meshes/finger_proximal.dae"/>
      </geometry>
      <material name="carbon_fiber">
        <color rgba="0.792156862745098 0.819607843137255 0.933333333333333 1"/>
      </material>
    </visual>
    <collision>
      <geometry>
        <mesh filename="package://kinova_description/meshes/finger_proximal.dae"/>
      </geometry>
    </collision>
    <inertial>
      <mass value="0.01"/>
      <origin xyz="0.022 0 0"/>
      <inertia ixx="7.8999684e-07" ixy="0" ixz="0" iyy="7.8999684e-07" iyz="0" izz="8e-08"/>
    </inertial>
  </link>
  <joint name="j2s7s300_joint_finger_1_a" type="revolute">
    <parent link="j2s7s300_link_7_a"/>
    <child link="j2s7s300_link_finger_1_a"/>
    <axis xyz="0 0 1"/>
    <origin rpy="-1.570796327 .649262481663582 1.35961148639407" xyz="0.00279 0.03126 -0.11467"/>
    <limit effort="2000" lower="0" upper="2" velocity="1"/>
  </joint>
  <transmission name="j2s7s300_joint_finger_1_trans">
    <type>transmission_interface/SimpleTransmission</type>
    <joint name="j2s7s300_joint_finger_1_a">
      <hardwareInterface>EffortJointInterface</hardwareInterface>
    </joint>
    <actuator name="j2s7s300_joint_finger_1_actuator">
      <hardwareInterface>EffortJointInterface</hardwareInterface>
      <mechanicalReduction>1</mechanicalReduction>
    </actuator>
  </transmission>
  <link name="j2s7s300_link_finger_tip_1_a">
    <visual>
      <geometry>
        <mesh filename="package://kinova_description/meshes/finger_distal.dae"/>
      </geometry>
      <material name="carbon_fiber">
        <color rgba="0.792156862745098 0.819607843137255 0.933333333333333 1"/>
      </material>
    </visual>
    <collision>
      <geometry>
        <mesh filename="package://kinova_description/meshes/finger_distal.dae"/>
      </geometry>
    </collision>
    <inertial>
      <mass value="0.01"/>
      <origin xyz="0.022 0 0"/>
      <inertia ixx="7.8999684e-07" ixy="0" ixz="0" iyy="7.8999684e-07" iyz="0" izz="8e-08"/>
    </inertial>
  </link>
  <joint name="j2s7s300_joint_finger_tip_1_a" type="fixed">
    <parent link="j2s7s300_link_finger_1_a"/>
    <child link="j2s7s300_link_finger_tip_1_a"/>
    <axis xyz="0 0 1"/>
    <origin rpy="0 0 0" xyz="0.044 -0.003 0"/>
    <limit effort="2000" lower="0" upper="2" velocity="1"/>
  </joint>
  <link name="j2s7s300_link_finger_2_a">
    <visual>
      <geometry>
        <mesh filename="package://kinova_description/meshes/finger_proximal.dae"/>
      </geometry>
      <material name="carbon_fiber">
        <color rgba="0.792156862745098 0.819607843137255 0.933333333333333 1"/>
      </material>
    </visual>
    <collision>
      <geometry>
        <mesh filename="package://kinova_description/meshes/finger_proximal.dae"/>
      </geometry>
    </collision>
    <inertial>
      <mass value="0.01"/>
      <origin xyz="0.022 0 0"/>
      <inertia ixx="7.8999684e-07" ixy="0" ixz="0" iyy="7.8999684e-07" iyz="0" izz="8e-08"/>
    </inertial>
  </link>
  <joint name="j2s7s300_joint_finger_2_a" type="revolute">
    <parent link="j2s7s300_link_7_a"/>
    <child link="j2s7s300_link_finger_2_a"/>
    <axis xyz="0 0 1"/>
    <origin rpy="-1.570796327 .649262481663582 -1.38614049188413" xyz="0.02226 -0.02707 -0.11482"/>
    <limit effort="2000" lower="0" upper="2" velocity="1"/>
  </joint>
  <transmission name="j2s7s300_joint_finger_2_trans">
    <type>transmission_interface/SimpleTransmission</type>
    <joint name="j2s7s300_joint_finger_2_a">
      <hardwareInterface>EffortJointInterface</hardwareInterface>
    </joint>
    <actuator name="j2s7s300_joint_finger_2_actuator">
      <hardwareInterface>EffortJointInterface</hardwareInterface>
      <mechanicalReduction>1</mechanicalReduction>
    </actuator>
  </transmission>
  <link name="j2s7s300_link_finger_tip_2_a">
    <visual>
      <geometry>
        <mesh filename="package://kinova_description/meshes/finger_distal.dae"/>
      </geometry>
      <material name="carbon_fiber">
        <color rgba="0.792156862745098 0.819607843137255 0.933333333333333 1"/>
      </material>
    </visual>
    <collision>
      <geometry>
        <mesh filename="package://kinova_description/meshes/finger_distal.dae"/>
      </geometry>
    </collision>
    <inertial>
      <mass value="0.01"/>
      <origin xyz="0.022 0 0"/>
      <inertia ixx="7.8999684e-07" ixy="0" ixz="0" iyy="7.8999684e-07" iyz="0" izz="8e-08"/>
    </inertial>
  </link>
  <joint name="j2s7s300_joint_finger_tip_2_a" type="fixed">
    <parent link="j2s7s300_link_finger_2_a"/>
    <child link="j2s7s300_link_finger_tip_2_a"/>
    <axis xyz="0 0 1"/>
    <origin rpy="0 0 0" xyz="0.044 -0.003 0"/>
    <limit effort="2000" lower="0" upper="2" velocity="1"/>
  </joint>
  <link name="j2s7s300_link_finger_3_a">
    <visual>
      <geometry>
        <mesh filename="package://kinova_description/meshes/finger_proximal.dae"/>
      </geometry>
      <material name="carbon_fiber">
        <color rgba="0.792156862745098 0.819607843137255 0.933333333333333 1"/>
      </material>
    </visual>
    <collision>
      <geometry>
        <mesh filename="package://kinova_description/meshes/finger_proximal.dae"/>
      </geometry>
    </collision>
    <inertial>
      <mass value="0.01"/>
      <origin xyz="0.022 0 0"/>
      <inertia ixx="7.8999684e-07" ixy="0" ixz="0" iyy="7.8999684e-07" iyz="0" izz="8e-08"/>
    </inertial>
  </link>
  <joint name="j2s7s300_joint_finger_3_a" type="revolute">
    <parent link="j2s7s300_link_7_a"/>
    <child link="j2s7s300_link_finger_3_a"/>
    <axis xyz="0 0 1"/>
    <origin rpy="-1.570796327 .649262481663582 -1.75545216211587" xyz="-0.02226 -0.02707 -0.11482"/>
    <limit effort="2000" lower="0" upper="2" velocity="1"/>
  </joint>
  <transmission name="j2s7s300_joint_finger_3_trans">
    <type>transmission_interface/SimpleTransmission</type>
    <joint name="j2s7s300_joint_finger_3_a">
      <hardwareInterface>EffortJointInterface</hardwareInterface>
    </joint>
    <actuator name="j2s7s300_joint_finger_3_actuator">
      <hardwareInterface>EffortJointInterface</hardwareInterface>
      <mechanicalReduction>1</mechanicalReduction>
    </actuator>
  </transmission>
  <link name="j2s7s300_link_finger_tip_3_a">
    <visual>
      <geometry>
        <mesh filename="package://kinova_description/meshes/finger_distal.dae"/>
      </geometry>
      <material name="carbon_fiber">
        <color rgba="0.792156862745098 0.819607843137255 0.933333333333333 1"/>
      </material>
    </visual>
    <collision>
      <geometry>
        <mesh filename="package://kinova_description/meshes/finger_distal.dae"/>
      </geometry>
    </collision>
    <inertial>
      <mass value="0.01"/>
      <origin xyz="0.022 0 0"/>
      <inertia ixx="7.8999684e-07" ixy="0" ixz="0" iyy="7.8999684e-07" iyz="0" izz="8e-08"/>
    </inertial>
  </link>
  <joint name="j2s7s300_joint_finger_tip_3_a" type="fixed">
    <parent link="j2s7s300_link_finger_3_a"/>
    <child link="j2s7s300_link_finger_tip_3_a"/>
    <axis xyz="0 0 1"/>
    <origin rpy="0 0 0" xyz="0.044 -0.003 0"/>
    <limit effort="2000" lower="0" upper="2" velocity="1"/>
  </joint>














  <link name="root_b">
    <visual>
      <origin rpy="0 0 0" xyz="0 0 0"/>
      <geometry>
        <box size="0 0 0"/>
      </geometry>
      <!--<material name="Black" /> -->
    </visual>
    <collision>
      <origin rpy="0 0 0" xyz="0 0 0"/>
      <geometry>
        <box size="0 0 0"/>
      </geometry>
    </collision>
  </link>
  <!-- for gazebo -->
  <joint name="connect_root_and_world_b" type="fixed">
    <child link="root_b"/>
    <parent link="world"/>
    <origin rpy="0 0 0" xyz="-0.1905 0.4 0.0"/>
  </joint>
  <!-- ros_control plugin -->
  <gazebo>
    <plugin filename="libgazebo_ros_control.so" name="gazebo_ros_control">
      <robotNamespace>j2s7s300</robotNamespace>
      <robotSimType>gazebo_ros_control/DefaultRobotHWSim</robotSimType>
    </plugin>
  </gazebo>
  <link name="j2s7s300_link_base_b">
    <visual>
      <geometry>
        <mesh filename="package://kinova_description/meshes/base.dae"/>
      </geometry>
      <material name="carbon_fiber">
        <color rgba="0.792156862745098 0.819607843137255 0.933333333333333 1"/>
      </material>
    </visual>
    <collision>
      <geometry>
        <mesh filename="package://kinova_description/meshes/base.dae"/>
      </geometry>
    </collision>
    <inertial>
      <mass value="0.46784"/>
      <origin rpy="0 0 0" xyz="0 0 0.1255"/>
      <inertia ixx="0.000951270861568" ixy="0" ixz="0" iyy="0.000951270861568" iyz="0" izz="0.000374272"/>
    </inertial>
  </link>
  <joint name="j2s7s300_joint_base_b" type="fixed">
    <parent link="root_b"/>
    <child link="j2s7s300_link_base_b"/>
    <axis xyz="0 0 0"/>
    <limit effort="2000" lower="0" upper="0" velocity="1"/>
    <origin rpy="0 0 0" xyz="0 0 0"/>
    <dynamics damping="0.0" friction="0.0"/>
  </joint>
  <link name="j2s7s300_link_1_b">
    <visual>
      <geometry>
        <mesh filename="package://kinova_description/meshes/shoulder.dae"/>
      </geometry>
      <material name="carbon_fiber">
        <color rgba="0.792156862745098 0.819607843137255 0.933333333333333 1"/>
      </material>
    </visual>
    <visual>
      <geometry>
        <mesh filename="package://kinova_description/meshes/ring_big.STL"/>
      </geometry>
    </visual>
    <collision>
      <geometry>
        <mesh filename="package://kinova_description/meshes/shoulder.dae"/>
      </geometry>
    </collision>
    <inertial>
      <mass value="0.7477"/>
      <origin xyz="0 -0.002 -0.0605"/>
      <inertia ixx="0.00152031725204" ixy="0" ixz="0" iyy="0.00152031725204" iyz="0" izz="0.00059816"/>
    </inertial>
  </link>
  <joint name="j2s7s300_joint_1_b" type="continuous">
    <parent link="j2s7s300_link_base_b"/>
    <child link="j2s7s300_link_1_b"/>
    <axis xyz="0 0 1"/>
    <limit effort="2000" lower="-6.28318530718" upper="6.28318530718" velocity="1"/>
    <origin rpy="0 3.14159265359 0" xyz="0 0 0.15675"/>
    <dynamics damping="0.0" friction="0.0"/>
  </joint>
  <transmission name="j2s7s300_joint_1_trans">
    <type>transmission_interface/SimpleTransmission</type>
    <joint name="j2s7s300_joint_1_b">
      <hardwareInterface>EffortJointInterface</hardwareInterface>
    </joint>
    <actuator name="j2s7s300_joint_1_bctuator">
      <hardwareInterface>EffortJointInterface</hardwareInterface>
      <mechanicalReduction>160</mechanicalReduction>
    </actuator>
  </transmission>
  <link name="j2s7s300_link_2_b">
    <visual>
      <geometry>
        <mesh filename="package://kinova_description/meshes/arm_half_1.dae"/>
      </geometry>
      <material name="carbon_fiber">
        <color rgba="0.792156862745098 0.819607843137255 0.933333333333333 1"/>
      </material>
    </visual>
    <visual>
      <geometry>
        <mesh filename="package://kinova_description/meshes/ring_big.STL"/>
      </geometry>
    </visual>
    <collision>
      <geometry>
        <mesh filename="package://kinova_description/meshes/arm_half_1.dae"/>
      </geometry>
    </collision>
    <inertial>
      <mass value="0.8447"/>
      <origin xyz="0 -0.103563213 0"/>
      <inertia ixx="0.00247073761701" ixy="0" ixz="0" iyy="0.000380115" iyz="0" izz="0.00247073761701"/>
    </inertial>
  </link>
  <joint name="j2s7s300_joint_2_b" type="revolute">
    <parent link="j2s7s300_link_1_b"/>
    <child link="j2s7s300_link_2_b"/>
    <axis xyz="0 0 1"/>
    <limit effort="2000" lower="0.820304748437" upper="5.46288055874" velocity="1"/>
    <origin rpy="-1.57079632679 0 3.14159265359" xyz="0 0.0016 -0.11875"/>
    <dynamics damping="0.0" friction="0.0"/>
  </joint>
  <transmission name="j2s7s300_joint_2_trans">
    <type>transmission_interface/SimpleTransmission</type>
    <joint name="j2s7s300_joint_2_b">
      <hardwareInterface>EffortJointInterface</hardwareInterface>
    </joint>
    <actuator name="j2s7s300_joint_2_bctuator">
      <hardwareInterface>EffortJointInterface</hardwareInterface>
      <mechanicalReduction>160</mechanicalReduction>
    </actuator>
  </transmission>
  <link name="j2s7s300_link_3_b">
    <visual>
      <geometry>
        <mesh filename="package://kinova_description/meshes/arm_half_2.dae"/>
      </geometry>
      <material name="carbon_fiber">
        <color rgba="0.792156862745098 0.819607843137255 0.933333333333333 1"/>
      </material>
    </visual>
    <visual>
      <geometry>
        <mesh filename="package://kinova_description/meshes/ring_big.STL"/>
      </geometry>
    </visual>
    <collision>
      <geometry>
        <mesh filename="package://kinova_description/meshes/arm_half_2.dae"/>
      </geometry>
    </collision>
    <inertial>
      <mass value="0.8447"/>
      <origin xyz="0 0 -0.1022447445"/>
      <inertia ixx="0.00247073761701" ixy="0" ixz="0" iyy="0.00247073761701" iyz="0" izz="0.000380115"/>
    </inertial>
  </link>
  <joint name="j2s7s300_joint_3_b" type="continuous">
    <parent link="j2s7s300_link_2_b"/>
    <child link="j2s7s300_link_3_b"/>
    <axis xyz="0 0 1"/>
    <limit effort="2000" lower="-6.28318530718" upper="6.28318530718" velocity="1"/>
    <origin rpy="-1.57079632679 0 0" xyz="0 -0.205 0"/>
    <dynamics damping="0.0" friction="0.0"/>
  </joint>
  <transmission name="j2s7s300_joint_3_trans">
    <type>transmission_interface/SimpleTransmission</type>
    <joint name="j2s7s300_joint_3_b">
      <hardwareInterface>EffortJointInterface</hardwareInterface>
    </joint>
    <actuator name="j2s7s300_joint_3_bctuator">
      <hardwareInterface>EffortJointInterface</hardwareInterface>
      <mechanicalReduction>160</mechanicalReduction>
    </actuator>
  </transmission>
  <link name="j2s7s300_link_4_b">
    <visual>
      <geometry>
        <mesh filename="package://kinova_description/meshes/forearm.dae"/>
      </geometry>
      <material name="carbon_fiber">
        <color rgba="0.792156862745098 0.819607843137255 0.933333333333333 1"/>
      </material>
    </visual>
    <visual>
      <geometry>
        <mesh filename="package://kinova_description/meshes/ring_small.STL"/>
      </geometry>
    </visual>
    <collision>
      <geometry>
        <mesh filename="package://kinova_description/meshes/forearm.dae"/>
      </geometry>
    </collision>
    <inertial>
      <mass value="0.6763"/>
      <origin xyz="0 0.081 -0.0086"/>
      <inertia ixx="0.00142022431908" ixy="0" ixz="0" iyy="0.000304335" iyz="0" izz="0.00142022431908"/>
    </inertial>
  </link>
  <joint name="j2s7s300_joint_4_b" type="revolute">
    <parent link="j2s7s300_link_3_b"/>
    <child link="j2s7s300_link_4_b"/>
    <axis xyz="0 0 1"/>
    <limit effort="2000" lower="0.523598775598" upper="5.75958653158" velocity="1"/>
    <origin rpy="1.57079632679 0 3.14159265359" xyz="0 0 -0.205"/>
    <dynamics damping="0.0" friction="0.0"/>
  </joint>
  <transmission name="j2s7s300_joint_4_trans">
    <type>transmission_interface/SimpleTransmission</type>
    <joint name="j2s7s300_joint_4_b">
      <hardwareInterface>EffortJointInterface</hardwareInterface>
    </joint>
    <actuator name="j2s7s300_joint_4_bctuator">
      <hardwareInterface>EffortJointInterface</hardwareInterface>
      <mechanicalReduction>160</mechanicalReduction>
    </actuator>
  </transmission>
  <link name="j2s7s300_link_5_b">
    <visual>
      <geometry>
        <mesh filename="package://kinova_description/meshes/wrist_spherical_1.dae"/>
      </geometry>
      <material name="carbon_fiber">
        <color rgba="0.792156862745098 0.819607843137255 0.933333333333333 1"/>
      </material>
    </visual>
    <visual>
      <geometry>
        <mesh filename="package://kinova_description/meshes/ring_small.STL"/>
      </geometry>
    </visual>
    <collision>
      <geometry>
        <mesh filename="package://kinova_description/meshes/wrist_spherical_1.dae"/>
      </geometry>
    </collision>
    <inertial>
      <mass value="0.463"/>
      <origin xyz="0 0.0028848942 -0.0541932613"/>
      <inertia ixx="0.0004321316048" ixy="0" ixz="0" iyy="0.0004321316048" iyz="0" izz="9.26e-05"/>
    </inertial>
  </link>
  <joint name="j2s7s300_joint_5_b" type="continuous">
    <parent link="j2s7s300_link_4_b"/>
    <child link="j2s7s300_link_5_b"/>
    <axis xyz="0 0 1"/>
    <limit effort="2000" lower="-6.28318530718" upper="6.28318530718" velocity="1"/>
    <origin rpy="-1.57079632679 0 3.14159265359" xyz="0 0.2073 -0.0114"/>
    <dynamics damping="0.0" friction="0.0"/>
  </joint>
  <transmission name="j2s7s300_joint_5_trans">
    <type>transmission_interface/SimpleTransmission</type>
    <joint name="j2s7s300_joint_5_b">
      <hardwareInterface>EffortJointInterface</hardwareInterface>
    </joint>
    <actuator name="j2s7s300_joint_5_bctuator">
      <hardwareInterface>EffortJointInterface</hardwareInterface>
      <mechanicalReduction>160</mechanicalReduction>
    </actuator>
  </transmission>
  <link name="j2s7s300_link_6_b">
    <visual>
      <geometry>
        <mesh filename="package://kinova_description/meshes/wrist_spherical_2.dae"/>
      </geometry>
      <material name="carbon_fiber">
        <color rgba="0.792156862745098 0.819607843137255 0.933333333333333 1"/>
      </material>
    </visual>
    <visual>
      <geometry>
        <mesh filename="package://kinova_description/meshes/ring_small.STL"/>
      </geometry>
    </visual>
    <collision>
      <geometry>
        <mesh filename="package://kinova_description/meshes/wrist_spherical_2.dae"/>
      </geometry>
    </collision>
    <inertial>
      <mass value="0.463"/>
      <origin xyz="0 0.0497208855 -0.0028562765"/>
      <inertia ixx="0.0004321316048" ixy="0" ixz="0" iyy="9.26e-05" iyz="0" izz="0.0004321316048"/>
    </inertial>
  </link>
  <joint name="j2s7s300_joint_6_b" type="revolute">
    <parent link="j2s7s300_link_5_b"/>
    <child link="j2s7s300_link_6_b"/>
    <axis xyz="0 0 1"/>
    <limit effort="2000" lower="1.1344640138" upper="5.14872129338" velocity="1"/>
    <origin rpy="1.57079632679 0 3.14159265359" xyz="0 0 -0.10375"/>
    <dynamics damping="0.0" friction="0.0"/>
  </joint>
  <transmission name="j2s7s300_joint_6_trans">
    <type>transmission_interface/SimpleTransmission</type>
    <joint name="j2s7s300_joint_6_b">
      <hardwareInterface>EffortJointInterface</hardwareInterface>
    </joint>
    <actuator name="j2s7s300_joint_6_bctuator">
      <hardwareInterface>EffortJointInterface</hardwareInterface>
      <mechanicalReduction>160</mechanicalReduction>
    </actuator>
  </transmission>
  <link name="j2s7s300_link_7_b">
    <visual>
      <geometry>
        <mesh filename="package://kinova_description/meshes/hand_3finger.dae"/>
      </geometry>
      <material name="carbon_fiber">
        <color rgba="0.792156862745098 0.819607843137255 0.933333333333333 1"/>
      </material>
    </visual>
    <visual>
      <geometry>
        <mesh filename="package://kinova_description/meshes/ring_small.STL"/>
      </geometry>
    </visual>
    <collision>
      <geometry>
        <mesh filename="package://kinova_description/meshes/hand_3finger.dae"/>
      </geometry>
    </collision>
    <inertial>
      <mass value="0.727"/>
      <origin xyz="0 0 -0.06"/>
      <inertia ixx="0.0003453236187" ixy="0" ixz="0" iyy="0.0003453236187" iyz="0" izz="0.0005816"/>
    </inertial>
  </link>
  <joint name="j2s7s300_joint_7_b" type="continuous">
    <parent link="j2s7s300_link_6_b"/>
    <child link="j2s7s300_link_7_b"/>
    <axis xyz="0 0 1"/>
    <limit effort="2000" lower="-6.28318530718" upper="6.28318530718" velocity="1"/>
    <origin rpy="-1.57079632679 0 3.14159265359" xyz="0 0.10375 0"/>
    <dynamics damping="0.0" friction="0.0"/>
  </joint>
  <transmission name="j2s7s300_joint_7_trans">
    <type>transmission_interface/SimpleTransmission</type>
    <joint name="j2s7s300_joint_7_b">
      <hardwareInterface>EffortJointInterface</hardwareInterface>
    </joint>
    <actuator name="j2s7s300_joint_7_bctuator">
      <hardwareInterface>EffortJointInterface</hardwareInterface>
      <mechanicalReduction>160</mechanicalReduction>
    </actuator>
  </transmission>
  <link name="j2s7s300_end_effector_b">
    <visual>
      <geometry>
        <box size="0 0 0"/>
      </geometry>
    </visual>
    <collision>
      <geometry>
        <box size="0 0 0"/>
      </geometry>
    </collision>
  </link>
  <joint name="j2s7s300_joint_end_effector_b" type="fixed">
    <parent link="j2s7s300_link_7_b"/>
    <child link="j2s7s300_end_effector_b"/>
    <axis xyz="0 0 0"/>
    <limit effort="2000" lower="0" upper="0" velocity="1"/>
    <origin rpy="3.14159265359 0 0" xyz="0 0 -0.1600"/>
  </joint>
  <link name="j2s7s300_link_finger_1_b">
    <visual>
      <geometry>
        <mesh filename="package://kinova_description/meshes/finger_proximal.dae"/>
      </geometry>
      <material name="carbon_fiber">
        <color rgba="0.792156862745098 0.819607843137255 0.933333333333333 1"/>
      </material>
    </visual>
    <collision>
      <geometry>
        <mesh filename="package://kinova_description/meshes/finger_proximal.dae"/>
      </geometry>
    </collision>
    <inertial>
      <mass value="0.01"/>
      <origin xyz="0.022 0 0"/>
      <inertia ixx="7.8999684e-07" ixy="0" ixz="0" iyy="7.8999684e-07" iyz="0" izz="8e-08"/>
    </inertial>
  </link>
  <joint name="j2s7s300_joint_finger_1_b" type="revolute">
    <parent link="j2s7s300_link_7_b"/>
    <child link="j2s7s300_link_finger_1_b"/>
    <axis xyz="0 0 1"/>
    <origin rpy="-1.570796327 .649262481663582 1.35961148639407" xyz="0.00279 0.03126 -0.11467"/>
    <limit effort="2000" lower="0" upper="2" velocity="1"/>
  </joint>
  <transmission name="j2s7s300_joint_finger_1_trans">
    <type>transmission_interface/SimpleTransmission</type>
    <joint name="j2s7s300_joint_finger_1_b">
      <hardwareInterface>EffortJointInterface</hardwareInterface>
    </joint>
    <actuator name="j2s7s300_joint_finger_1_bctuator">
      <hardwareInterface>EffortJointInterface</hardwareInterface>
      <mechanicalReduction>1</mechanicalReduction>
    </actuator>
  </transmission>
  <link name="j2s7s300_link_finger_tip_1_b">
    <visual>
      <geometry>
        <mesh filename="package://kinova_description/meshes/finger_distal.dae"/>
      </geometry>
      <material name="carbon_fiber">
        <color rgba="0.792156862745098 0.819607843137255 0.933333333333333 1"/>
      </material>
    </visual>
    <collision>
      <geometry>
        <mesh filename="package://kinova_description/meshes/finger_distal.dae"/>
      </geometry>
    </collision>
    <inertial>
      <mass value="0.01"/>
      <origin xyz="0.022 0 0"/>
      <inertia ixx="7.8999684e-07" ixy="0" ixz="0" iyy="7.8999684e-07" iyz="0" izz="8e-08"/>
    </inertial>
  </link>
  <joint name="j2s7s300_joint_finger_tip_1_b" type="fixed">
    <parent link="j2s7s300_link_finger_1_b"/>
    <child link="j2s7s300_link_finger_tip_1_b"/>
    <axis xyz="0 0 1"/>
    <origin rpy="0 0 0" xyz="0.044 -0.003 0"/>
    <limit effort="2000" lower="0" upper="2" velocity="1"/>
  </joint>
  <link name="j2s7s300_link_finger_2_b">
    <visual>
      <geometry>
        <mesh filename="package://kinova_description/meshes/finger_proximal.dae"/>
      </geometry>
      <material name="carbon_fiber">
        <color rgba="0.792156862745098 0.819607843137255 0.933333333333333 1"/>
      </material>
    </visual>
    <collision>
      <geometry>
        <mesh filename="package://kinova_description/meshes/finger_proximal.dae"/>
      </geometry>
    </collision>
    <inertial>
      <mass value="0.01"/>
      <origin xyz="0.022 0 0"/>
      <inertia ixx="7.8999684e-07" ixy="0" ixz="0" iyy="7.8999684e-07" iyz="0" izz="8e-08"/>
    </inertial>
  </link>
  <joint name="j2s7s300_joint_finger_2_b" type="revolute">
    <parent link="j2s7s300_link_7_b"/>
    <child link="j2s7s300_link_finger_2_b"/>
    <axis xyz="0 0 1"/>
    <origin rpy="-1.570796327 .649262481663582 -1.38614049188413" xyz="0.02226 -0.02707 -0.11482"/>
    <limit effort="2000" lower="0" upper="2" velocity="1"/>
  </joint>
  <transmission name="j2s7s300_joint_finger_2_trans">
    <type>transmission_interface/SimpleTransmission</type>
    <joint name="j2s7s300_joint_finger_2_b">
      <hardwareInterface>EffortJointInterface</hardwareInterface>
    </joint>
    <actuator name="j2s7s300_joint_finger_2_bctuator">
      <hardwareInterface>EffortJointInterface</hardwareInterface>
      <mechanicalReduction>1</mechanicalReduction>
    </actuator>
  </transmission>
  <link name="j2s7s300_link_finger_tip_2_b">
    <visual>
      <geometry>
        <mesh filename="package://kinova_description/meshes/finger_distal.dae"/>
      </geometry>
      <material name="carbon_fiber">
        <color rgba="0.792156862745098 0.819607843137255 0.933333333333333 1"/>
      </material>
    </visual>
    <collision>
      <geometry>
        <mesh filename="package://kinova_description/meshes/finger_distal.dae"/>
      </geometry>
    </collision>
    <inertial>
      <mass value="0.01"/>
      <origin xyz="0.022 0 0"/>
      <inertia ixx="7.8999684e-07" ixy="0" ixz="0" iyy="7.8999684e-07" iyz="0" izz="8e-08"/>
    </inertial>
  </link>
  <joint name="j2s7s300_joint_finger_tip_2_b" type="fixed">
    <parent link="j2s7s300_link_finger_2_b"/>
    <child link="j2s7s300_link_finger_tip_2_b"/>
    <axis xyz="0 0 1"/>
    <origin rpy="0 0 0" xyz="0.044 -0.003 0"/>
    <limit effort="2000" lower="0" upper="2" velocity="1"/>
  </joint>
  <link name="j2s7s300_link_finger_3_b">
    <visual>
      <geometry>
        <mesh filename="package://kinova_description/meshes/finger_proximal.dae"/>
      </geometry>
      <material name="carbon_fiber">
        <color rgba="0.792156862745098 0.819607843137255 0.933333333333333 1"/>
      </material>
    </visual>
    <collision>
      <geometry>
        <mesh filename="package://kinova_description/meshes/finger_proximal.dae"/>
      </geometry>
    </collision>
    <inertial>
      <mass value="0.01"/>
      <origin xyz="0.022 0 0"/>
      <inertia ixx="7.8999684e-07" ixy="0" ixz="0" iyy="7.8999684e-07" iyz="0" izz="8e-08"/>
    </inertial>
  </link>
  <joint name="j2s7s300_joint_finger_3_b" type="revolute">
    <parent link="j2s7s300_link_7_b"/>
    <child link="j2s7s300_link_finger_3_b"/>
    <axis xyz="0 0 1"/>
    <origin rpy="-1.570796327 .649262481663582 -1.75545216211587" xyz="-0.02226 -0.02707 -0.11482"/>
    <limit effort="2000" lower="0" upper="2" velocity="1"/>
  </joint>
  <transmission name="j2s7s300_joint_finger_3_trans">
    <type>transmission_interface/SimpleTransmission</type>
    <joint name="j2s7s300_joint_finger_3_b">
      <hardwareInterface>EffortJointInterface</hardwareInterface>
    </joint>
    <actuator name="j2s7s300_joint_finger_3_bctuator">
      <hardwareInterface>EffortJointInterface</hardwareInterface>
      <mechanicalReduction>1</mechanicalReduction>
    </actuator>
  </transmission>
  <link name="j2s7s300_link_finger_tip_3_b">
    <visual>
      <geometry>
        <mesh filename="package://kinova_description/meshes/finger_distal.dae"/>
      </geometry>
      <material name="carbon_fiber">
        <color rgba="0.792156862745098 0.819607843137255 0.933333333333333 1"/>
      </material>
    </visual>
    <collision>
      <geometry>
        <mesh filename="package://kinova_description/meshes/finger_distal.dae"/>
      </geometry>
    </collision>
    <inertial>
      <mass value="0.01"/>
      <origin xyz="0.022 0 0"/>
      <inertia ixx="7.8999684e-07" ixy="0" ixz="0" iyy="7.8999684e-07" iyz="0" izz="8e-08"/>
    </inertial>
  </link>
  <joint name="j2s7s300_joint_finger_tip_3_b" type="fixed">
    <parent link="j2s7s300_link_finger_3_b"/>
    <child link="j2s7s300_link_finger_tip_3_b"/>
    <axis xyz="0 0 1"/>
    <origin rpy="0 0 0" xyz="0.044 -0.003 0"/>
    <limit effort="2000" lower="0" upper="2" velocity="1"/>
  </joint>



</robot>
